<?xml version="1.0" encoding="UTF-8"?>
<testng-results skipped="0" failed="1" total="1" passed="0">
  <reporter-output>
  </reporter-output>
  <suite name="Default suite" duration-ms="12352" started-at="2018-10-12T01:05:22Z" finished-at="2018-10-12T01:05:35Z">
    <groups>
    </groups>
    <test name="Default test" duration-ms="12352" started-at="2018-10-12T01:05:22Z" finished-at="2018-10-12T01:05:35Z">
      <class name="com.was.qa.testcases.HomePageTest">
        <test-method status="PASS" signature="setUp()[pri:0, instance:com.was.qa.testcases.HomePageTest@ae45eb6]" name="setUp" is-config="true" duration-ms="11430" started-at="2018-10-11T21:05:22Z" finished-at="2018-10-11T21:05:34Z">
          <reporter-output>
          </reporter-output>
        </test-method> <!-- setUp -->
        <test-method status="FAIL" signature="validateUserTest()[pri:0, instance:com.was.qa.testcases.HomePageTest@ae45eb6]" name="validateUserTest" duration-ms="61" started-at="2018-10-11T21:05:34Z" finished-at="2018-10-11T21:05:34Z">
          <exception class="java.lang.AssertionError">
            <message>
              <![CDATA[expected [username] but found [Settings]]]>
            </message>
            <full-stacktrace>
              <![CDATA[java.lang.AssertionError: expected [username] but found [Settings]
	at org.testng.Assert.fail(Assert.java:94)
	at org.testng.Assert.failNotEquals(Assert.java:494)
	at org.testng.Assert.assertEquals(Assert.java:123)
	at org.testng.Assert.assertEquals(Assert.java:176)
	at org.testng.Assert.assertEquals(Assert.java:186)
	at com.was.qa.testcases.HomePageTest.validateUserTest(HomePageTest.java:86)
	at sun.reflect.NativeMethodAccessorImpl.invoke0(Native Method)
	at sun.reflect.NativeMethodAccessorImpl.invoke(Unknown Source)
	at sun.reflect.DelegatingMethodAccessorImpl.invoke(Unknown Source)
	at java.lang.reflect.Method.invoke(Unknown Source)
	at org.testng.internal.MethodInvocationHelper.invokeMethod(MethodInvocationHelper.java:80)
	at org.testng.internal.Invoker.invokeMethod(Invoker.java:714)
	at org.testng.internal.Invoker.invokeTestMethod(Invoker.java:901)
	at org.testng.internal.Invoker.invokeTestMethods(Invoker.java:1231)
	at org.testng.internal.TestMethodWorker.invokeTestMethods(TestMethodWorker.java:127)
	at org.testng.internal.TestMethodWorker.run(TestMethodWorker.java:111)
	at org.testng.TestRunner.privateRun(TestRunner.java:767)
	at org.testng.TestRunner.run(TestRunner.java:617)
	at org.testng.SuiteRunner.runTest(SuiteRunner.java:334)
	at org.testng.SuiteRunner.runSequentially(SuiteRunner.java:329)
	at org.testng.SuiteRunner.privateRun(SuiteRunner.java:291)
	at org.testng.SuiteRunner.run(SuiteRunner.java:240)
	at org.testng.SuiteRunnerWorker.runSuite(SuiteRunnerWorker.java:52)
	at org.testng.SuiteRunnerWorker.run(SuiteRunnerWorker.java:86)
	at org.testng.TestNG.runSuitesSequentially(TestNG.java:1198)
	at org.testng.TestNG.runSuitesLocally(TestNG.java:1123)
	at org.testng.TestNG.run(TestNG.java:1031)
	at org.testng.remote.AbstractRemoteTestNG.run(AbstractRemoteTestNG.java:114)
	at org.testng.remote.RemoteTestNG.initAndRun(RemoteTestNG.java:251)
	at org.testng.remote.RemoteTestNG.main(RemoteTestNG.java:77)
]]>
            </full-stacktrace>
          </exception> <!-- java.lang.AssertionError -->
          <reporter-output>
          </reporter-output>
        </test-method> <!-- validateUserTest -->
        <test-method status="PASS" signature="cleanUp()[pri:0, instance:com.was.qa.testcases.HomePageTest@ae45eb6]" name="cleanUp" is-config="true" duration-ms="839" started-at="2018-10-11T21:05:34Z" finished-at="2018-10-11T21:05:35Z">
          <reporter-output>
          </reporter-output>
        </test-method> <!-- cleanUp -->
      </class> <!-- com.was.qa.testcases.HomePageTest -->
    </test> <!-- Default test -->
  </suite> <!-- Default suite -->
</testng-results>
